<robot name="onshape">
  <!-- A new empty root link -->
  <link name="base_link">
    <!-- Optionally add minimal inertia to avoid warnings -->
    <inertial>
      <origin xyz="0 0 0" rpy="0 0 0"/>
      <mass value="0.001"/>
      <inertia ixx="1e-6" ixy="0" ixz="0" iyy="1e-6" iyz="0" izz="1e-6"/>
    </inertial>
  </link>
  
  <!-- Palm -->
  <link name="leap_rh_palm">
    <visual>
      <origin xyz="-0.020095249652862544332 0.025757756134899473244 -0.034722403578460216134" rpy="0 0 0" />
      <geometry>
        <mesh filename="meshes_obj/palm_lower.obj"/>
      </geometry>
      <material name="palm_lower_material">
        <color rgba="0.60392156862745094426 0.14901960784313725283 0.14901960784313725283 1.0"/>
      </material>
    </visual>
    <collision>
      <origin xyz="-0.020095249652862544332 0.025757756134899473244 -0.034722403578460216134" rpy="0 0 0" />
      <geometry>
        <mesh filename="meshes_obj/palm_lower.obj"/>
      </geometry>
    </collision>
    <inertial>
      <origin xyz="0 0 0" rpy="0 0 0"/>
      <mass value="0.237" />
      <inertia ixx="0.000354094" ixy="-0.000001193" ixz="-0.000002445" iyy="0.000260915" iyz="-0.000002905" izz="0.000529257" />
    </inertial>
  </link>

  <!-- Index Finger (if) -->
  <link name="leap_rh_if_bs">
    <visual>
      <origin xyz="0.0084069022611744960438 0.0077662438597169954416 0.014657354985032912051" rpy="1.6375789613220999807e-15 -1.0210473302491019535e-30 1.7177968783327987474e-31" />
      <geometry>
        <mesh filename="meshes_obj/mcp_joint.obj"/>
      </geometry>
      <material name="mcp_joint_material">
        <color rgba="0.86666666666666669627 0.86666666666666669627 0.050980392156862744391 1.0"/>
      </material>
    </visual>
    <collision>
      <origin xyz="0.0084069022611744960438 0.0077662438597169954416 0.014657354985032912051" rpy="1.6375789613220999807e-15 -1.0210473302491019535e-30 1.7177968783327987474e-31" />
      <geometry>
        <mesh filename="meshes_obj/mcp_joint.obj"/>
      </geometry>
    </collision>
    <inertial>
      <origin xyz="0 0 0" rpy="0 0 0"/>
      <mass value="0.044" />
      <inertia ixx="0.000011499" ixy="0.000003049" ixz="0.000000121" iyy="0.000007796" iyz="0.000000112" izz="0.000014759" />
    </inertial>
  </link>

  <link name="leap_rh_if_px">
    <visual>
      <origin xyz="0.0096433630922713280131 0.00029999999999998951117 0.00078403401041737645627" rpy="-1.570796326794896558 -1.570796326794896336 0" />
      <geometry>
        <mesh filename="meshes_obj/pip.obj"/>
      </geometry>
      <material name="pip_material">
        <color rgba="0.74901960784313725839 0.74901960784313725839 0.74901960784313725839 1.0"/>
      </material>
    </visual>
    <collision>
      <origin xyz="0.0096433630922713280131 0.00029999999999998951117 0.00078403401041737645627" rpy="-1.570796326794896558 -1.570796326794896336 0" />
      <geometry>
        <mesh filename="meshes_obj/pip.obj"/>
      </geometry>
    </collision>
    <inertial>
      <origin xyz="0 0 0" rpy="0 0 0"/>
      <mass value="0.032" />
      <inertia ixx="0.000004798" ixy="0.000000012" ixz="0.000000004" iyy="0.000002862" iyz="0.000000011" izz="0.000004234" />
    </inertial>
  </link>

  <link name="leap_rh_if_md">
    <visual>
      <origin xyz="0.021133352895225002849 -0.0084321191467048792201 0.0097850881620952408213" rpy="-3.141592653589793116 4.5075111242164408299e-32 4.4395481053923607589e-32" />
      <geometry>
        <mesh filename="meshes_obj/dip.obj"/>
      </geometry>
      <material name="dip_material">
        <color rgba="0.86666666666666669627 0.86666666666666669627 0.050980392156862744391 1.0"/>
      </material>
    </visual>
    <collision>
      <origin xyz="0.021133352895225002849 -0.0084321191467048792201 0.0097850881620952408213" rpy="-3.141592653589793116 4.5075111242164408299e-32 4.4395481053923607589e-32" />
      <geometry>
        <mesh filename="meshes_obj/dip.obj"/>
      </geometry>
    </collision>
    <inertial>
      <origin xyz="0 0 0" rpy="0 0 0"/>
      <mass value="0.037" />
      <inertia ixx="0.000005542" ixy="-0.000000607" ixz="-0.000000017" iyy="0.000005727" iyz="-0.000000023" izz="0.000006682" />
    </inertial>
  </link>

  <link name="leap_rh_if_ds">
    <visual>
      <origin xyz="0.013286424108533503169 -0.0061142383865419869249 0.014499999999999497666" rpy="3.141592653589793116 1.1993117970061734707e-33 4.4395481053923607589e-32" />
      <geometry>
        <mesh filename="meshes_obj/fingertip.obj"/>
      </geometry>
      <material name="fingertip_material">
        <color rgba="0.86666666666666669627 0.86666666666666669627 0.050980392156862744391 1.0"/>
      </material>
    </visual>
    <collision name="leap_rh_if_ds_collision_FROGGERCOL">
      <origin xyz="0.013286424108533503169 -0.0061142383865419869249 0.014499999999999497666" rpy="3.141592653589793116 1.1993117970061734707e-33 4.4395481053923607589e-32" />
      <geometry>
        <mesh filename="meshes_obj/fingertip.obj"/>
      </geometry>
    </collision>
    <inertial>
      <origin xyz="0 0 0" rpy="0 0 0"/>
      <mass value="0.016" />
      <inertia ixx="0.000003368" ixy="0.000000115" ixz="0" iyy="0.000001556" iyz="0" izz="0.000002863" />
    </inertial>
  </link>

  <!-- Joints for Index Finger -->
  <joint name="leap_rh_if_mcp" type="revolute">
    <origin xyz="-0.012200000000000007713 0.038099999999999994982 0.014500000000000000736" rpy="-1.570796326794896558 -1.0065212660796336576e-15 1.5707963267948943376" />
    <parent link="leap_rh_if_bs"/>
    <child link="leap_rh_if_px"/>
    <axis xyz="0 0 -1"/>
    <limit effort="0.95" velocity="8.48" lower="-1.047" upper="1.047"/>
    <joint_properties friction="0.0"/>
  </joint>

  <joint name="leap_rh_if_axl" type="revolute">
    <origin xyz="-0.0070952496528625457958 0.023057756134899472233 -0.01872240357846021927" rpy="1.5707963267948950037 1.5707963267948945596 0" />
    <parent link="leap_rh_palm"/>
    <child link="leap_rh_if_bs"/>
    <axis xyz="0 0 -1"/>
    <limit effort="0.95" velocity="8.48" lower="-0.314" upper="2.23"/>
    <joint_properties friction="0.0"/>
  </joint>

  <joint name="leap_rh_if_pip" type="revolute">
    <origin xyz="0.01499999999999996822 0.014299999999999904801 -0.012999999999999824196" rpy="1.5707963267948958919 -1.570796326794896336 0" />
    <parent link="leap_rh_if_px"/>
    <child link="leap_rh_if_md"/>
    <axis xyz="0 0 -1"/>
    <limit effort="0.95" velocity="8.48" lower="-0.506" upper="1.885"/>
    <joint_properties friction="0.0"/>
  </joint>

  <joint name="leap_rh_if_dip" type="revolute">
    <origin xyz="-4.0880582495572692636e-09 -0.036100004210367367397 0.00020000000000007858714" rpy="4.5935029425113685044e-17 -2.8730071914463794583e-16 4.4395481053923607589e-32" />
    <parent link="leap_rh_if_md"/>
    <child link="leap_rh_if_ds"/>
    <axis xyz="0 0 -1"/>
    <limit effort="0.95" velocity="8.48" lower="-0.366" upper="2.042"/>
    <joint_properties friction="0.0"/>
  </joint>

  <!-- Middle Finger (mf) -->
  <link name="leap_rh_mf_bs">
    <visual>
      <origin xyz="0.0084069022611744960438 0.0077662438597169954416 0.014657354985032913786" rpy="1.6375789613220999807e-15 -1.0076465469034000467e-30 2.1209300131419907151e-61" />
      <geometry>
        <mesh filename="meshes_obj/mcp_joint.obj"/>
      </geometry>
      <material name="mcp_joint_material">
        <color rgba="0.86666666666666669627 0.86666666666666669627 0.050980392156862744391 1.0"/>
      </material>
    </visual>
    <collision>
      <origin xyz="0.0084069022611744960438 0.0077662438597169954416 0.014657354985032913786" rpy="1.6375789613220999807e-15 -1.0076465469034000467e-30 2.1209300131419907151e-61" />
      <geometry>
        <mesh filename="meshes_obj/mcp_joint.obj"/>
      </geometry>
    </collision>
    <inertial>
      <origin xyz="0 0 0" rpy="0 0 0"/>
      <mass value="0.044" />
      <inertia ixx="0.000011499" ixy="0.000003049" ixz="0.000000121" iyy="0.000007796" iyz="0.000000112" izz="0.000014759" />
    </inertial>
  </link>

  <link name="leap_rh_mf_px">
    <visual>
      <origin xyz="0.0096433630922713280131 0.00029999999999998951117 0.00078403401041737645627" rpy="-1.570796326794896558 -1.570796326794896336 0" />
      <geometry>
        <mesh filename="meshes_obj/pip.obj"/>
      </geometry>
      <material name="pip_material">
        <color rgba="0.74901960784313725839 0.74901960784313725839 0.74901960784313725839 1.0"/>
      </material>
    </visual>
    <collision>
      <origin xyz="0.0096433630922713280131 0.00029999999999998951117 0.00078403401041737645627" rpy="-1.570796326794896558 -1.570796326794896336 0" />
      <geometry>
        <mesh filename="meshes_obj/pip.obj"/>
      </geometry>
    </collision>
    <inertial>
      <origin xyz="0 0 0" rpy="0 0 0"/>
      <mass value="0.032" />
      <inertia ixx="0.000004798" ixy="0.000000012" ixz="0.000000004" iyy="0.000002862" iyz="0.000000011" izz="0.000004234" />
    </inertial>
  </link>

  <link name="leap_rh_mf_md">
    <visual>
      <origin xyz="0.021133352895225002849 -0.0084321191467048792201 0.0097850881620952373519" rpy="-3.141592653589793116 2.1146933785271955805e-32 1.4408183216511868558e-31" />
      <geometry>
        <mesh filename="meshes_obj/dip.obj"/>
      </geometry>
      <material name="dip_material">
        <color rgba="0.86666666666666669627 0.86666666666666669627 0.050980392156862744391 1.0"/>
      </material>
    </visual>
    <collision>
      <origin xyz="0.021133352895225002849 -0.0084321191467048792201 0.0097850881620952373519" rpy="-3.141592653589793116 2.1146933785271955805e-32 1.4408183216511868558e-31" />
      <geometry>
        <mesh filename="meshes_obj/dip.obj"/>
      </geometry>
    </collision>
    <inertial>
      <origin xyz="0 0 0" rpy="0 0 0"/>
      <mass value="0.037" />
      <inertia ixx="0.000005542" ixy="-0.000000607" ixz="-0.000000017" iyy="0.000005727" iyz="-0.000000023" izz="0.000006682" />
    </inertial>
  </link>

  <link name="leap_rh_mf_ds">
    <visual>
      <origin xyz="0.013286424108533503169 -0.0061142383865419982006 0.014499999999999492462" rpy="3.141592653589793116 -4.3179597882835943107e-33 1.4408183216511868558e-31" />
      <geometry>
        <mesh filename="meshes_obj/fingertip.obj"/>
      </geometry>
      <material name="fingertip_material">
        <color rgba="0.86666666666666669627 0.86666666666666669627 0.050980392156862744391 1.0"/>
      </material>
    </visual>
    <collision name="leap_rh_mf_ds_collision_FROGGERCOL">
      <origin xyz="0.013286424108533503169 -0.0061142383865419982006 0.014499999999999492462" rpy="3.141592653589793116 -4.3179597882835943107e-33 1.4408183216511868558e-31" />
      <geometry>
        <mesh filename="meshes_obj/fingertip.obj"/>
      </geometry>
    </collision>
    <inertial>
      <origin xyz="0 0 0" rpy="0 0 0"/>
      <mass value="0.016" />
      <inertia ixx="0.000003368" ixy="0.000000115" ixz="0" iyy="0.000001556" iyz="0" izz="0.000002863" />
    </inertial>
  </link>

  <!-- Joints for Middle Finger -->
  <joint name="leap_rh_mf_mcp" type="revolute">
    <origin xyz="-0.012200000000000002509 0.038099999999999988043 0.014499999999999999001" rpy="-1.570796326794896558 1.6094417208041279902e-15 1.5707963267948943376" />
    <parent link="leap_rh_mf_bs"/>
    <child link="leap_rh_mf_px"/>
    <axis xyz="0 0 -1"/>
    <limit effort="0.95" velocity="8.48" lower="-1.047" upper="1.047"/>
    <joint_properties friction="0.0"/>
  </joint>

  <joint name="leap_rh_mf_axl" type="revolute">
    <origin xyz="-0.0070952496528625388569 -0.022392243865100525113 -0.018722403578460229678" rpy="1.570796326794896558 1.570796326794896558 0" />
    <parent link="leap_rh_palm"/>
    <child link="leap_rh_mf_bs"/>
    <axis xyz="0 0 -1"/>
    <limit effort="0.95" velocity="8.48" lower="-0.314" upper="2.23"/>
    <joint_properties friction="0.0"/>
  </joint>

  <joint name="leap_rh_mf_pip" type="revolute">
    <origin xyz="0.01499999999999996475 0.014299999999999986333 -0.013000000000000025424" rpy="1.5707963267948958919 -1.570796326794896336 0" />
    <parent link="leap_rh_mf_px"/>
    <child link="leap_rh_mf_md"/>
    <axis xyz="0 0 -1"/>
    <limit effort="0.95" velocity="8.48" lower="-0.506" upper="1.885"/>
    <joint_properties friction="0.0"/>
  </joint>

  <joint name="leap_rh_mf_dip" type="revolute">
    <origin xyz="1.0408340855860842566e-16 -0.036099999999999875244 0.00020000000000007511769" rpy="4.5935029425113654229e-17 -2.8730071914463794583e-16 1.4408183216511868558e-31" />
    <parent link="leap_rh_mf_md"/>
    <child link="leap_rh_mf_ds"/>
    <axis xyz="0 0 -1"/>
    <limit effort="0.95" velocity="8.48" lower="-0.366" upper="2.042"/>
    <joint_properties friction="0.0"/>
  </joint>

  <!-- Ring Finger (rf) -->
  <link name="leap_rh_rf_bs">
    <visual>
      <origin xyz="0.0084069022611744995133 0.0077662438597169963089 0.014657354985032913786" rpy="1.6375789613220999807e-15 -1.0059504988632626953e-30 5.729641584552035421e-32" />
      <geometry>
        <mesh filename="meshes_obj/mcp_joint.obj"/>
      </geometry>
      <material name="mcp_joint_material">
        <color rgba="0.86666666666666669627 0.86666666666666669627 0.050980392156862744391 1.0"/>
      </material>
    </visual>
    <collision>
      <origin xyz="0.0084069022611744995133 0.0077662438597169963089 0.014657354985032913786" rpy="1.6375789613220999807e-15 -1.0059504988632626953e-30 5.729641584552035421e-32" />
      <geometry>
        <mesh filename="meshes_obj/mcp_joint.obj"/>
      </geometry>
    </collision>
    <inertial>
      <origin xyz="0 0 0" rpy="0 0 0"/>
      <mass value="0.044" />
      <inertia ixx="0.000011499" ixy="0" ixz="0.000000121" iyy="0.000007796" iyz="0" izz="0.000014759" />
    </inertial>
  </link>

  <link name="leap_rh_rf_px">
    <visual>
      <origin xyz="0.0096433630922713280131 0.00029999999999999124589 0.00078403401041737645627" rpy="-1.570796326794896558 -1.570796326794896336 0" />
      <geometry>
        <mesh filename="meshes_obj/pip.obj"/>
      </geometry>
      <material name="pip_material">
        <color rgba="0.74901960784313725839 0.74901960784313725839 0.74901960784313725839 1.0"/>
      </material>
    </visual>
    <collision>
      <origin xyz="0.0096433630922713280131 0.00029999999999999124589 0.00078403401041737645627" rpy="-1.570796326794896558 -1.570796326794896336 0" />
      <geometry>
        <mesh filename="meshes_obj/pip.obj"/>
      </geometry>
    </collision>
    <inertial>
      <origin xyz="0 0 0" rpy="0 0 0"/>
      <mass value="0.032" />
      <inertia ixx="0.000004798" ixy="0.000000012" ixz="0.000000004" iyy="0.000002862" iyz="0.000000011" izz="0.000004234" />
    </inertial>
  </link>

  <link name="leap_rh_rf_md">
    <visual>
      <origin xyz="0.021133352895225006318 -0.0084321191467048653423 0.0097850881620952373519" rpy="-3.141592653589793116 -1.4095651113919093005e-33 1.5565411607615035382e-32" />
      <geometry>
        <mesh filename="meshes_obj/dip.obj"/>
      </geometry>
      <material name="dip_material">
        <color rgba="0.86666666666666669627 0.86666666666666669627 0.050980392156862744391 1.0"/>
      </material>
    </visual>
    <collision>
      <origin xyz="0.021133352895225006318 -0.0084321191467048653423 0.0097850881620952373519" rpy="-3.141592653589793116 -1.4095651113919093005e-33 1.5565411607615035382e-32" />
      <geometry>
        <mesh filename="meshes_obj/dip.obj"/>
      </geometry>
    </collision>
    <inertial>
      <origin xyz="0 0 0" rpy="0 0 0"/>
      <mass value="0.037" />
      <inertia ixx="0.000005542" ixy="-0.000000607" ixz="-0.000000017" iyy="0.000005727" iyz="-0.000000023" izz="0.000006682" />
    </inertial>
  </link>

  <link name="leap_rh_rf_ds">
    <visual>
      <origin xyz="0.013286424108533501434 -0.0061142383865419869249 0.0144999999999994994" rpy="3.141592653589793116 8.6170716950575402125e-33 1.5565411607615035382e-32" />
      <geometry>
        <mesh filename="meshes_obj/fingertip.obj"/>
      </geometry>
      <material name="fingertip_material">
        <color rgba="0.86666666666666669627 0.86666666666666669627 0.050980392156862744391 1.0"/>
      </material>
    </visual>
    <collision name="leap_rh_rf_ds_collision_FROGGERCOL">
      <origin xyz="0.013286424108533501434 -0.0061142383865419869249 0.0144999999999994994" rpy="3.141592653589793116 8.6170716950575402125e-33 1.5565411607615035382e-32" />
      <geometry>
        <mesh filename="meshes_obj/fingertip.obj"/>
      </geometry>
    </collision>
    <inertial>
      <origin xyz="0 0 0" rpy="0 0 0"/>
      <mass value="0.016" />
      <inertia ixx="0.000003368" ixy="0.000000115" ixz="0" iyy="0.000001556" iyz="0" izz="0.000002863" />
    </inertial>
  </link>

  <!-- Joints for Ring Finger -->
  <joint name="leap_rh_rf_mcp" type="revolute">
    <origin xyz="-0.012200000000000004244 0.038100000000000001921 0.014500000000000000736" rpy="-1.570796326794896558 -1.0065212760057939085e-15 1.5707963267948943376" />
    <parent link="leap_rh_rf_bs"/>
    <child link="leap_rh_rf_px"/>
    <axis xyz="0 0 -1"/>
    <limit effort="0.95" velocity="8.48" lower="-1.047" upper="1.047"/>
    <joint_properties friction="0.0"/>
  </joint>

  <joint name="leap_rh_rf_axl" type="revolute">
    <origin xyz="-0.0070952454426398371343 -0.067842243865100515521 -0.018722407666402932774" rpy="1.5707963267948950037 1.5707963267948945596 0" />
    <parent link="leap_rh_palm"/>
    <child link="leap_rh_rf_bs"/>
    <axis xyz="0 0 -1"/>
    <limit effort="0.95" velocity="8.48" lower="-0.314" upper="2.23"/>
    <joint_properties friction="0.0"/>
  </joint>

  <joint name="leap_rh_rf_pip" type="revolute">
    <origin xyz="0.01499999999999996822 0.014299999999999989803 -0.013000000000000025424" rpy="1.5707963267948958919 -1.570796326794896336 0" />
    <parent link="leap_rh_rf_px"/>
    <child link="leap_rh_rf_md"/>
    <axis xyz="0 0 -1"/>
    <limit effort="0.95" velocity="8.48" lower="-0.506" upper="1.885"/>
    <joint_properties friction="0.0"/>
  </joint>

  <joint name="leap_rh_rf_dip" type="revolute">
    <origin xyz="1.0234868508263161857e-16 -0.036099999999999868305 0.00020000000000007858714" rpy="4.5935029425113685044e-17 -2.8730071914463799514e-16 1.5565411607615035382e-32" />
    <parent link="leap_rh_rf_md"/>
    <child link="leap_rh_rf_ds"/>
    <axis xyz="0 0 -1"/>
    <limit effort="0.95" velocity="8.48" lower="-0.366" upper="2.042"/>
    <joint_properties friction="0.0"/>
  </joint>

  <!-- Thumb -->
  <!-- In this URDF the thumb group consists of four links.
       We reinterpret the original “pip_4” as the thumb metacarpal. -->
  <link name="leap_rh_th_mp">
    <visual>
      <origin xyz="-0.0053566369077286714317 0.00029999999999999991951 0.00078403401041737819099" rpy="-1.570796326794896558 -1.570796326794896336 0" />
      <geometry>
        <mesh filename="meshes_obj/pip.obj"/>
      </geometry>
      <material name="pip_material">
        <color rgba="0.74901960784313725839 0.74901960784313725839 0.74901960784313725839 1.0"/>
      </material>
    </visual>
    <collision>
      <origin xyz="-0.0053566369077286714317 0.00029999999999999991951 0.00078403401041737819099" rpy="-1.570796326794896558 -1.570796326794896336 0" />
      <geometry>
        <mesh filename="meshes_obj/pip.obj"/>
      </geometry>
    </collision>
    <inertial>
      <origin xyz="0 0 0" rpy="0 0 0"/>
      <mass value="0.032" />
      <inertia ixx="0.000004798" ixy="0.000000012" ixz="0.000000004" iyy="0.000002862" iyz="0.000000011" izz="0.000004234" />
    </inertial>
  </link>

  <link name="leap_rh_th_bs">
    <visual>
      <origin xyz="0.011961920770611186859 -5.3082538364890297089e-16 -0.015852648956664199681" rpy="1.570796326794896558 1.6050198443300152637e-46 -3.9204996250525192755e-59" />
      <geometry>
        <mesh filename="meshes_obj/thumb_pip.obj"/>
      </geometry>
      <material name="thumb_pip_material">
        <color rgba="0.86666666666666669627 0.86666666666666669627 0.050980392156862744391 1.0"/>
      </material>
    </visual>
    <collision>
      <origin xyz="0.011961920770611186859 -5.3082538364890297089e-16 -0.015852648956664199681" rpy="1.570796326794896558 1.6050198443300152637e-46 -3.9204996250525192755e-59" />
      <geometry>
        <mesh filename="meshes_obj/thumb_pip.obj"/>
      </geometry>
    </collision>
    <inertial>
      <origin xyz="0 0 0" rpy="0 0 0"/>
      <mass value="0.003" />
      <inertia ixx="0.000000593" ixy="0" ixz="0" iyy="0.000000549" iyz="0" izz="0.000000224" />
    </inertial>
  </link>

  <link name="leap_rh_th_px">
    <visual>
      <origin xyz="0.043968715707239175439 0.057952952973709198625 -0.0086286764493694757122" rpy="1.9428902930940098942e-16 3.2751579226442200773e-15 1.1123758529657360012e-46" />
      <geometry>
        <mesh filename="meshes_obj/thumb_dip.obj"/>
      </geometry>
      <material name="thumb_dip_material">
        <color rgba="0.86666666666666669627 0.86666666666666669627 0.050980392156862744391 1.0"/>
      </material>
    </visual>
    <collision>
      <origin xyz="0.043968715707239175439 0.057952952973709198625 -0.0086286764493694757122" rpy="1.9428902930940098942e-16 3.2751579226442200773e-15 1.1123758529657360012e-46" />
      <geometry>
        <mesh filename="meshes_obj/thumb_dip.obj"/>
      </geometry>
    </collision>
    <inertial>
      <origin xyz="0 0 0" rpy="0 0 0"/>
      <mass value="0.038" />
      <inertia ixx="0.000008474" ixy="0.000000241" ixz="0.000000026" iyy="0.000003841" iyz="0.000000025" izz="0.000007679" />
    </inertial>
  </link>

  <link name="leap_rh_th_ds">
    <visual>
      <origin xyz="0.062559538462667388381 0.078459682911396988469 0.048992911807332215068" rpy="4.3790577010156367543e-47 -3.3306690738754701143e-16 1.2042408677791935383e-46" />
      <geometry>
        <mesh filename="meshes_obj/thumb_fingertip.obj"/>
      </geometry>
      <material name="thumb_fingertip_material">
        <color rgba="0.60392156862745094426 0.14901960784313725283 0.14901960784313725283 1.0"/>
      </material>
    </visual>
    <collision name="leap_rh_th_ds_collision_FROGGERCOL">
      <origin xyz="0.062559538462667388381 0.078459682911396988469 0.048992911807332215068" rpy="4.3790577010156367543e-47 -3.3306690738754701143e-16 1.2042408677791935383e-46" />
      <geometry>
        <mesh filename="meshes_obj/thumb_fingertip.obj"/>
      </geometry>
    </collision>
    <inertial>
      <origin xyz="0 0 0" rpy="0 0 0"/>
      <mass value="0.049" />
      <inertia ixx="0.000020372" ixy="-0.000000489" ixz="-0.00000003" iyy="0.000004336" iyz="-0.000000097" izz="0.000019845" />
    </inertial>
  </link>

  <!-- A fixed joint that rotates the palm link about Y -->
  <joint name="base_to_palm" type="fixed">
    <parent link="base_link"/>
    <child link="leap_rh_palm"/>
    <!-- For a 90-degree rotation about Y, use rpy="0 1.5708 0" -->
    <origin xyz="0 0.035 0.1" rpy="0 -1.5708 0"/>
  </joint>

  <!-- Joints for Thumb -->
  <joint name="leap_rh_th_cmc" type="revolute">
    <origin xyz="-0.069395249652862533996 -0.0012422438651005258004 -0.021622403578460215601" rpy="-8.2381766464939424156e-17 1.5707963267948956698 0" />
    <parent link="leap_rh_palm" />
    <child link="leap_rh_th_mp" />
    <axis xyz="0 0 -1"/>
    <limit effort="0.95" velocity="8.48" lower="-0.349" upper="2.094"/>
    <joint_properties friction="0.0"/>
  </joint>

  <joint name="leap_rh_th_axl" type="revolute">
    <origin xyz="-2.7755575615628913511e-17 0.014300000000000005415 -0.013000000000000011546" rpy="1.5707963267948958919 -1.570796326794896336 0" />
    <parent link="leap_rh_th_mp" />
    <child link="leap_rh_th_bs" />
    <axis xyz="0 0 -1"/>
    <limit effort="0.95" velocity="8.48" lower="-0.47" upper="2.443"/>
    <joint_properties friction="0.0"/>
  </joint>

  <joint name="leap_rh_th_mcp" type="revolute">
    <origin xyz="0 0.014499999999999966041 -0.017000000000000053263" rpy="-1.570796326794896558 1.6050198443300131245e-46 -1.9721522630516624601e-31" />
    <parent link="leap_rh_th_bs" />
    <child link="leap_rh_th_px" />
    <axis xyz="0 0 -1"/>
    <limit effort="0.95" velocity="8.48" lower="-1.20" upper="1.90"/>
    <joint_properties friction="0.0"/>
  </joint>

  <joint name="leap_rh_th_ipl" type="revolute">
    <origin xyz="-1.249000902703301108e-16 0.046599999999999863753 0.00019999999999997710581" rpy="1.5063958491491781023e-44 5.4234187233935260503e-31 3.141592653589793116" />
    <parent link="leap_rh_th_px" />
    <child link="leap_rh_th_ds" />
    <axis xyz="0 0 -1"/>
    <limit effort="0.95" velocity="8.48" lower="-1.34" upper="1.88"/>
    <joint_properties friction="0.0"/>
  </joint>

  <!-- Palm sampling -->
  <link name="leap_rh_palm_FROGGERSAMPLE" />

  <!-- <joint name="dummy_sampling_joint" type="fixed">
    <parent link="leap_rh_palm"/>
    <child link="leap_rh_palm_FROGGERSAMPLE"/>
    <origin xyz="-0.1 -0.055 0.0" rpy="1.57079632679489678 1.1239611599647231752e-28 3.1415926535897908956"/>
  </joint> -->

  <joint name="dummy_sampling_joint" type="fixed">
    <parent link="base_link"/>
    <child link="leap_rh_palm_FROGGERSAMPLE"/>
    <origin xyz="0.03 0.0 0.07" rpy="0 0 0"/>
  </joint>

</robot>
